Workbook

Sheet mes
B2: AUDITORIA MENSUAL 5S
B4: CB | D4: AULA /TALLER | H4: RESPONSABLE AULA/TALLER: | O4: CALIFICACION PREVIA:
B5: TEL | D5: CLASE: | H5: AUDITOR: | O5: CALIFICACION FINAL: | P5: =+P56 -> 0
B6: TEM | D6: ASIGNATURA: | H6: FECHA: | O6: NIVEL ACTUAL:
C9: Nivel | D9: 0 | E9: 1 | F9: 2 | G9: 3 | H9: 4 | I9: 5
C10: Status | D10: No Iniciado | E10: Actividad de inicio | F10: Amplia Actividad | G10: Nivel minimo requerido | H10: Nivle Medio | I10: Mejor Practica
C11: Puntos | D11: 0-10 | E11: 10-40 | F11: 40-70 | G11: 70-100 | H11: 100-130 | I11: 130-150
J14: PUNTAJE | Q14: OBSERVACIONES
J15: 0 | K15: 1 | L15: 2 | M15: 3 | N15: 4 | O15: 5 | P15: Total
B16: SELECCIÓN | C16: 1 | D16: Componentes, materiales y partes | F16: Se encuentran los niveles necesarios de materiales/elementos. Residuos y elementos sin uso están en contenedores claramente identificados. | P16: =SUM(J16:O16) -> 0
C17: 2 | D17: Maquinas, gabinetes, muebles, bancos, escritorios | F17: Solo los elementos necesarios estan en uso y se encuentran operables. No hay elementos rotos que deban ser descartados o reparados. | P17: =SUM(J17:O17) -> 0
C18: 3 | D18: Herramientas y equipos | F18: Todas las herramientas necsarias están en uso y operables. Hay cosas innecesarias en los armarios. | P18: =SUM(J18:O18) -> 0
C19: 4 | D19: Cartelera / Información | F19: ¿Los registros de actividad con tarjetas rojas y hallazgos estan actualizados? | P19: =SUM(J19:O19) -> 0
C20: 5 | D20: Ambiente | F20: Existen objetos innecesarios o basura en el piso. Las areas de circulación están libres de objetos. | P20: =SUM(J20:O20) -> 0
N21: TOTAL | P21: =SUM(P16:P20) -> 0
B23: ORDEN | C23: 6 | D23: Lay out | F23: Maquinas, herramientas, estanterias, contenedores estan dispuestos de manera lógica y promoviendo un flujo de trabajo agil y ordenado en el área. | P23: =SUM(J23:O23) -> 0
C24: 7 | D24: Marcado de pasillos y suelos | F24: Los pasillos y sendas se encuentran marcados y liberados | P24: =SUM(J24:O24) -> 0
C25: 8 | D25: Documentación y señales visuales | F25: Se encuentran solo los documentos /carpetas necesarias para el trabajo. Están guardadas, ordenadas y rotuladas. | P25: =SUM(J25:O25) -> 0
C26: 9 | D26: Control visual y almacenamiento | F26: Los elementos estan correctamente identificados. La cartelería es clara, apropiada y prolija. | P26: =SUM(J26:O26) -> 0
C27: 10 | D27: Lugares para herramientas y accesorios | F27: Herramientas y accesorios son arreglados y guardados en orden, limpios y en un lugar específico de facil localización. | P27: =SUM(J27:O27) -> 0
C28: 11 | D28: Elementos fuera de lugar | F28: Hay elementos sin ubicación especifica. Obstruyen el orden y limpieza del lugar. | P28: =SUM(J28:O28) -> 0
C29: 12 | D29: Almacenamiento de materiales peligrosos | F29: Liquidos, solventes y otros quimicos se encuentran claramente identificados. Se encuentran disponibles sus hojas de seguridad. No hay derrames. | P29: =SUM(J29:O29) -> 0
C30: 13 | D30: Salidas de emergencia. Elementos de seguridad | F30: Los elementos de seguridad están visibles y sin obstrucciones. Las rutas de escape y los lugares de peligro estan identificados y despejados. | P30: =SUM(J30:O30) -> 0
C31: 14 | D31: Mantenimiento de equipos | F31: Se llevan registros del mantenimiento de los equipos. Se informan posibles mejoras. | P31: =SUM(J31:O31) -> 0
N32: TOTAL | P32: =SUM(P23:P31) -> 0
B34: LIMPIEZA | C34: 15 | D34: Estado de pisos / tachos | F34: Los pisos están limpios, libres de suciedad, residuos o líquidos. El exterior de los tachos está limpio e identificado. | P34: =SUM(J34:O34) -> 0
C35: 16 | D35: Maquinas / equipos | F35: Se realiza una rutina de limpieza. No hay tierra, suciedad, residuos entre o en las máquinas o equipos. | P35: =SUM(J35:O35) -> 0
C36: 17 | D36: Elementos de limpieza | F36: Todo el equipo de limpieza está ubicado en un lugar específico y disponible facilmente. | P36: =SUM(J36:O36) -> 0
C37: 18 | D37: Limpieza mas alla de lo propio | F37: Todo el area se ve ordenada | P37: =SUM(J37:O37) -> 0
C38: 19 | D38: Disciplina de limpieza | F38: Cuando hay tiempo disponible, los alumnos habitualmente y automáticamente ordenan y limpian sus espacios de trabajo. | P38: =SUM(J38:O38) -> 0
C39: 20 | D39: Plan de mejoras | F39: Donde sea aplicable se implementan nuevas estrategias para evitar la generación de residuos, según principios 5S. Existe un programa con responsables y plazos. | P39: =SUM(J39:O39) -> 0
N40: TOTAL | P40: =SUM(P34:P39) -> 0
B42: ESTANDARIZACION | C42: 21 | D42: Control visual | F42: Tableros o sistemas de información digitales son accesible al personal del area | P42: =SUM(J42:O42) -> 0
C43: 22 | D43: Auditorias 5S | F43: Se realizan auditorias de 5S regularmente y los resultados son expuestos y compartidos. | P43: =SUM(J43:O43) -> 0
C44: 23 | D44: Seguridad | F44: Los alumnos conocen y respetan las normas de seguridad del área. | P44: =SUM(J44:O44) -> 0
C45: 24 | D45: Actividadades estándar | F45: Se utilizan estandares para mantener organizadas y productivas las actividades. | P45: =SUM(J45:O45) -> 0
C46: 25 | D46: Revision del ciclo 5S | F46: Se aplican consistentemente las 3 primeras S. | P46: =SUM(J46:O46) -> 0
N47: TOTAL | P47: =SUM(P42:P46) -> 0
B49: DISCIPLINA | C49: 26 | D49: Mantenimiento | F49: El equipo es capacitado en 5S, se realizan actividades sistematicas, los docentes y alumnos se involucran. | P49: =SUM(J49:O49) -> 0
C50: 27 | D50: Area de responsabilidad | F50: Cumplen las normas del codigo de convivencia. Se utilizan los elementos de protección personal, incluyendo el uniforme. Se investigan y divulgan los accidentes. | P50: =SUM(J50:O50) -> 0
...

Sheet TALLER 1
B2: AUDITORIA MENSUAL 5S
B4: CB | D4: AULA /TALLER | H4: RESPONSABLE AULA/TALLER: | O4: CALIFICACION PREVIA:
B5: TEL | D5: CLASE: | H5: AUDITOR: | O5: CALIFICACION FINAL: | P5: =+P56 -> 0
B6: TEM | D6: ASIGNATURA: | H6: FECHA: | O6: NIVEL ACTUAL:
C9: Nivel | D9: 0 | E9: 1 | F9: 2 | G9: 3 | H9: 4 | I9: 5
C10: Status | D10: No Iniciado | E10: Actividad de inicio | F10: Amplia Actividad | G10: Nivel minimo requerido | H10: Nivle Medio | I10: Mejor Practica
C11: Puntos | D11: 0-10 | E11: 10-40 | F11: 40-70 | G11: 70-100 | H11: 100-130 | I11: 130-150
J14: PUNTAJE | Q14: OBSERVACIONES
J15: 0 | K15: 1 | L15: 2 | M15: 3 | N15: 4 | O15: 5 | P15: Total
B16: SELECCIÓN | C16: 1 | D16: Componentes, materiales y partes | F16: Se encuentran los niveles necesarios de materiales/elementos. Residuos y elementos sin uso están en contenedores claramente identificados. | P16: =SUM(J16:O16) -> 0
C17: 2 | D17: Maquinas, gabinetes, muebles, bancos, escritorios | F17: Solo los elementos necesarios estan en uso y se encuentran operables. No hay elementos rotos que deban ser descartados o reparados. | P17: =SUM(J17:O17) -> 0
C18: 3 | D18: Herramientas y equipos | F18: Todas las herramientas necsarias están en uso y operables. Hay cosas innecesarias en los armarios. | P18: =SUM(J18:O18) -> 0
C19: 4 | D19: Cartelera / Información | F19: ¿Los registros de actividad con tarjetas rojas y hallazgos estan actualizados? | P19: =SUM(J19:O19) -> 0
C20: 5 | D20: Ambiente | F20: Existen objetos innecesarios o basura en el piso. Las areas de circulación están libres de objetos. | P20: =SUM(J20:O20) -> 0
N21: TOTAL | P21: =SUM(P16:P20) -> 0
B23: ORDEN | C23: 6 | D23: Lay out | F23: Maquinas, herramientas, estanterias, contenedores estan dispuestos de manera lógica y promoviendo un flujo de trabajo agil y ordenado en el área. | P23: =SUM(J23:O23) -> 0
C24: 7 | D24: Marcado de pasillos y suelos | F24: Los pasillos y sendas se encuentran marcados y liberados | P24: =SUM(J24:O24) -> 0
C25: 8 | D25: Documentación y señales visuales | F25: Se encuentran solo los documentos /carpetas necesarias para el trabajo. Están guardadas, ordenadas y rotuladas. | P25: =SUM(J25:O25) -> 0
C26: 9 | D26: Control visual y almacenamiento | F26: Los elementos estan correctamente identificados. La cartelería es clara, apropiada y prolija. | P26: =SUM(J26:O26) -> 0
C27: 10 | D27: Lugares para herramientas y accesorios | F27: Herramientas y accesorios son arreglados y guardados en orden, limpios y en un lugar específico de facil localización. | P27: =SUM(J27:O27) -> 0
C28: 11 | D28: Elementos fuera de lugar | F28: Hay elementos sin ubicación especifica. Obstruyen el orden y limpieza del lugar. | P28: =SUM(J28:O28) -> 0
C29: 12 | D29: Almacenamiento de materiales peligrosos | F29: Liquidos, solventes y otros quimicos se encuentran claramente identificados. Se encuentran disponibles sus hojas de seguridad. No hay derrames. | P29: =SUM(J29:O29) -> 0
C30: 13 | D30: Salidas de emergencia. Elementos de seguridad | F30: Los elementos de seguridad están visibles y sin obstrucciones. Las rutas de escape y los lugares de peligro estan identificados y despejados. | P30: =SUM(J30:O30) -> 0
C31: 14 | D31: Mantenimiento de equipos | F31: Se llevan registros del mantenimiento de los equipos. Se informan posibles mejoras. | P31: =SUM(J31:O31) -> 0
N32: TOTAL | P32: =SUM(P23:P31) -> 0
B34: LIMPIEZA | C34: 15 | D34: Estado de pisos / tachos | F34: Los pisos están limpios, libres de suciedad, residuos o líquidos. El exterior de los tachos está limpio e identificado. | P34: =SUM(J34:O34) -> 0
C35: 16 | D35: Maquinas / equipos | F35: Se realiza una rutina de limpieza. No hay tierra, suciedad, residuos entre o en las máquinas o equipos. | P35: =SUM(J35:O35) -> 0
C36: 17 | D36: Elementos de limpieza | F36: Todo el equipo de limpieza está ubicado en un lugar específico y disponible facilmente. | P36: =SUM(J36:O36) -> 0
C37: 18 | D37: Limpieza mas alla de lo propio | F37: Todo el area se ve ordenada | P37: =SUM(J37:O37) -> 0
C38: 19 | D38: Disciplina de limpieza | F38: Cuando hay tiempo disponible, los alumnos habitualmente y automáticamente ordenan y limpian sus espacios de trabajo. | P38: =SUM(J38:O38) -> 0
C39: 20 | D39: Plan de mejoras | F39: Donde sea aplicable se implementan nuevas estrategias para evitar la generación de residuos, según principios 5S. Existe un programa con responsables y plazos. | P39: =SUM(J39:O39) -> 0
N40: TOTAL | P40: =SUM(P34:P39) -> 0
B42: ESTANDARIZACION | C42: 21 | D42: Control visual | F42: Tableros o sistemas de información digitales son accesible al personal del area | P42: =SUM(J42:O42) -> 0
C43: 22 | D43: Auditorias 5S | F43: Se realizan auditorias de 5S regularmente y los resultados son expuestos y compartidos. | P43: =SUM(J43:O43) -> 0
C44: 23 | D44: Seguridad | F44: Los alumnos conocen y respetan las normas de seguridad del área. | P44: =SUM(J44:O44) -> 0
C45: 24 | D45: Actividadades estándar | F45: Se utilizan estandares para mantener organizadas y productivas las actividades. | P45: =SUM(J45:O45) -> 0
C46: 25 | D46: Revision del ciclo 5S | F46: Se aplican consistentemente las 3 primeras S. | P46: =SUM(J46:O46) -> 0
N47: TOTAL | P47: =SUM(P42:P46) -> 0
B49: DISCIPLINA | C49: 26 | D49: Mantenimiento | F49: El equipo es capacitado en 5S, se realizan actividades sistematicas, los docentes y alumnos se involucran. | P49: =SUM(J49:O49) -> 0
C50: 27 | D50: Area de responsabilidad | F50: Cumplen las normas del codigo de convivencia. Se utilizan los elementos de protección personal, incluyendo el uniforme. Se investigan y divulgan los accidentes. | P50: =SUM(J50:O50) -> 0
...

Sheet MODELO
B2: AUDITORIA MENSUAL 5S
B4: CB | D4: AULA /TALLER | H4: RESPONSABLE AULA/TALLER: | O4: CALIFICACION PREVIA:
B5: TEL | D5: CLASE: | H5: AUDITOR: | O5: CALIFICACION FINAL: | P5: =+P56 -> 0
B6: TEM | D6: ASIGNATURA: | H6: FECHA: | O6: NIVEL ACTUAL:
C9: Puntaje | D9: 0 | E9: 1 | F9: 2 | G9: 3 | H9: 4 | I9: 5
C10: Status | D10: No Iniciado | E10: Actividad de inicio | F10: Amplia Actividad | G10: Nivel minimo requerido | H10: Nivle Medio | I10: Mejor Practica
C11: Puntaje final | D11: 0-10 | E11: 10-40 | F11: 40-70 | G11: 70-100 | H11: 100-130 | I11: 130-150
J14: PUNTAJE | Q14: OBSERVACIONES
J15: 0 | K15: 1 | L15: 2 | M15: 3 | N15: 4 | O15: 5 | P15: Total
B16: SELECCIÓN | C16: 1 | D16: Componentes, materiales y partes | F16: Se encuentran los niveles necesarios de materiales/elementos. Residuos y elementos sin uso están en contenedores claramente identificados. | P16: =SUM(J16:O16) -> 0
C17: 2 | D17: Maquinas, gabinetes, muebles, bancos, escritorios | F17: Solo los elementos necesarios estan en uso y se encuentran operables. No hay elementos rotos que deban ser descartados o reparados. | P17: =SUM(J17:O17) -> 0
C18: 3 | D18: Herramientas y equipos | F18: Todas las herramientas necsarias están en uso y operables. Hay cosas innecesarias en los armarios. | P18: =SUM(J18:O18) -> 0
C19: 4 | D19: Cartelera / Información | F19: ¿Los registros de actividad con tarjetas rojas y hallazgos estan actualizados? | P19: =SUM(J19:O19) -> 0
C20: 5 | D20: Ambiente | F20: Existen objetos innecesarios o basura en el piso. Las areas de circulación están libres de objetos. | P20: =SUM(J20:O20) -> 0
N21: TOTAL | P21: =SUM(P16:P20) -> 0
B23: ORDEN | C23: 6 | D23: Lay out | F23: Maquinas, herramientas, estanterias, contenedores estan dispuestos de manera lógica y promoviendo un flujo de trabajo agil y ordenado en el área. | P23: =SUM(J23:O23) -> 0
C24: 7 | D24: Marcado de pasillos y suelos | F24: Los pasillos y sendas se encuentran marcados y liberados | P24: =SUM(J24:O24) -> 0
C25: 8 | D25: Documentación y señales visuales | F25: Se encuentran solo los documentos /carpetas necesarias para el trabajo. Están guardadas, ordenadas y rotuladas. | P25: =SUM(J25:O25) -> 0
C26: 9 | D26: Control visual y almacenamiento | F26: Los elementos estan correctamente identificados. La cartelería es clara, apropiada y prolija. | P26: =SUM(J26:O26) -> 0
C27: 10 | D27: Lugares para herramientas y accesorios | F27: Herramientas y accesorios son arreglados y guardados en orden, limpios y en un lugar específico de facil localización. | P27: =SUM(J27:O27) -> 0
C28: 11 | D28: Elementos fuera de lugar | F28: Hay elementos sin ubicación especifica. Obstruyen el orden y limpieza del lugar. | P28: =SUM(J28:O28) -> 0
C29: 12 | D29: Almacenamiento de materiales peligrosos | F29: Liquidos, solventes y otros quimicos se encuentran claramente identificados. Se encuentran disponibles sus hojas de seguridad. No hay derrames. | P29: =SUM(J29:O29) -> 0
C30: 13 | D30: Salidas de emergencia. Elementos de seguridad | F30: Los elementos de seguridad están visibles y sin obstrucciones. Las rutas de escape y los lugares de peligro estan identificados y despejados. | P30: =SUM(J30:O30) -> 0
C31: 14 | D31: Mantenimiento de equipos | F31: Se llevan registros del mantenimiento de los equipos. Se informan posibles mejoras. | P31: =SUM(J31:O31) -> 0
N32: TOTAL | P32: =SUM(P23:P31) -> 0
B34: LIMPIEZA | C34: 15 | D34: Estado de pisos / tachos | F34: Los pisos están limpios, libres de suciedad, residuos o líquidos. El exterior de los tachos está limpio e identificado. | P34: =SUM(J34:O34) -> 0
C35: 16 | D35: Maquinas / equipos | F35: Se realiza una rutina de limpieza. No hay tierra, suciedad, residuos entre o en las máquinas o equipos. | P35: =SUM(J35:O35) -> 0
C36: 17 | D36: Elementos de limpieza | F36: Todo el equipo de limpieza está ubicado en un lugar específico y disponible facilmente. | P36: =SUM(J36:O36) -> 0
C37: 18 | D37: Limpieza mas alla de lo propio | F37: Todo el area se ve ordenada | P37: =SUM(J37:O37) -> 0
C38: 19 | D38: Disciplina de limpieza | F38: Cuando hay tiempo disponible, los alumnos habitualmente y automáticamente ordenan y limpian sus espacios de trabajo. | P38: =SUM(J38:O38) -> 0
C39: 20 | D39: Plan de mejoras | F39: Donde sea aplicable se implementan nuevas estrategias para evitar la generación de residuos, según principios 5S. Existe un programa con responsables y plazos. | P39: =SUM(J39:O39) -> 0
N40: TOTAL | P40: =SUM(P34:P39) -> 0
B42: ESTANDARIZACION | C42: 21 | D42: Control visual | F42: Tableros o sistemas de información digitales son accesible al personal del area | P42: =SUM(J42:O42) -> 0
C43: 22 | D43: Auditorias 5S | F43: Se realizan auditorias de 5S regularmente y los resultados son expuestos y compartidos. | P43: =SUM(J43:O43) -> 0
C44: 23 | D44: Seguridad | F44: Los alumnos conocen y respetan las normas de seguridad del área. | P44: =SUM(J44:O44) -> 0
C45: 24 | D45: Actividadades estándar | F45: Se utilizan estandares para mantener organizadas y productivas las actividades. | P45: =SUM(J45:O45) -> 0
C46: 25 | D46: Revision del ciclo 5S | F46: Se aplican consistentemente las 3 primeras S. | P46: =SUM(J46:O46) -> 0
N47: TOTAL | P47: =SUM(P42:P46) -> 0
B49: DISCIPLINA | C49: 26 | D49: Mantenimiento | F49: El equipo es capacitado en 5S, se realizan actividades sistematicas, los docentes y alumnos se involucran. | P49: =SUM(J49:O49) -> 0
C50: 27 | D50: Area de responsabilidad | F50: Cumplen las normas del codigo de convivencia. Se utilizan los elementos de protección personal, incluyendo el uniforme. Se investigan y divulgan los accidentes. | P50: =SUM(J50:O50) -> 0
...

Sheet TALLER 2
B2: AUDITORIA MENSUAL 5S
B4: CB | D4: AULA /TALLER | H4: RESPONSABLE AULA/TALLER: | O4: CALIFICACION PREVIA:
B5: TEL | D5: CLASE: | H5: AUDITOR: | O5: CALIFICACION FINAL: | P5: =+P56 -> 0
B6: TEM | D6: ASIGNATURA: | H6: FECHA: | O6: NIVEL ACTUAL:
C9: Nivel | D9: 0 | E9: 1 | F9: 2 | G9: 3 | H9: 4 | I9: 5
C10: Status | D10: No Iniciado | E10: Actividad de inicio | F10: Amplia Actividad | G10: Nivel minimo requerido | H10: Nivle Medio | I10: Mejor Practica
C11: Puntos | D11: 0-10 | E11: 10-40 | F11: 40-70 | G11: 70-100 | H11: 100-130 | I11: 130-150
J14: PUNTAJE | Q14: OBSERVACIONES
J15: 0 | K15: 1 | L15: 2 | M15: 3 | N15: 4 | O15: 5 | P15: Total
B16: SELECCIÓN | C16: 1 | D16: Componentes, materiales y partes | F16: Se encuentran los niveles necesarios de materiales/elementos. Residuos y elementos sin uso están en contenedores claramente identificados. | P16: =SUM(J16:O16) -> 0
C17: 2 | D17: Maquinas, gabinetes, muebles, bancos, escritorios | F17: Solo los elementos necesarios estan en uso y se encuentran operables. No hay elementos rotos que deban ser descartados o reparados. | P17: =SUM(J17:O17) -> 0
C18: 3 | D18: Herramientas y equipos | F18: Todas las herramientas necsarias están en uso y operables. Hay cosas innecesarias en los armarios. | P18: =SUM(J18:O18) -> 0
C19: 4 | D19: Cartelera / Información | F19: ¿Los registros de actividad con tarjetas rojas y hallazgos estan actualizados? | P19: =SUM(J19:O19) -> 0
C20: 5 | D20: Ambiente | F20: Existen objetos innecesarios o basura en el piso. Las areas de circulación están libres de objetos. | P20: =SUM(J20:O20) -> 0
N21: TOTAL | P21: =SUM(P16:P20) -> 0
B23: ORDEN | C23: 6 | D23: Lay out | F23: Maquinas, herramientas, estanterias, contenedores estan dispuestos de manera lógica y promoviendo un flujo de trabajo agil y ordenado en el área. | P23: =SUM(J23:O23) -> 0
C24: 7 | D24: Marcado de pasillos y suelos | F24: Los pasillos y sendas se encuentran marcados y liberados | P24: =SUM(J24:O24) -> 0
C25: 8 | D25: Documentación y señales visuales | F25: Se encuentran solo los documentos /carpetas necesarias para el trabajo. Están guardadas, ordenadas y rotuladas. | P25: =SUM(J25:O25) -> 0
C26: 9 | D26: Control visual y almacenamiento | F26: Los elementos estan correctamente identificados. La cartelería es clara, apropiada y prolija. | P26: =SUM(J26:O26) -> 0
C27: 10 | D27: Lugares para herramientas y accesorios | F27: Herramientas y accesorios son arreglados y guardados en orden, limpios y en un lugar específico de facil localización. | P27: =SUM(J27:O27) -> 0
C28: 11 | D28: Elementos fuera de lugar | F28: Hay elementos sin ubicación especifica. Obstruyen el orden y limpieza del lugar. | P28: =SUM(J28:O28) -> 0
C29: 12 | D29: Almacenamiento de materiales peligrosos | F29: Liquidos, solventes y otros quimicos se encuentran claramente identificados. Se encuentran disponibles sus hojas de seguridad. No hay derrames. | P29: =SUM(J29:O29) -> 0
C30: 13 | D30: Salidas de emergencia. Elementos de seguridad | F30: Los elementos de seguridad están visibles y sin obstrucciones. Las rutas de escape y los lugares de peligro estan identificados y despejados. | P30: =SUM(J30:O30) -> 0
C31: 14 | D31: Mantenimiento de equipos | F31: Se llevan registros del mantenimiento de los equipos. Se informan posibles mejoras. | P31: =SUM(J31:O31) -> 0
N32: TOTAL | P32: =SUM(P23:P31) -> 0
B34: LIMPIEZA | C34: 15 | D34: Estado de pisos / tachos | F34: Los pisos están limpios, libres de suciedad, residuos o líquidos. El exterior de los tachos está limpio e identificado. | P34: =SUM(J34:O34) -> 0
C35: 16 | D35: Maquinas / equipos | F35: Se realiza una rutina de limpieza. No hay tierra, suciedad, residuos entre o en las máquinas o equipos. | P35: =SUM(J35:O35) -> 0
C36: 17 | D36: Elementos de limpieza | F36: Todo el equipo de limpieza está ubicado en un lugar específico y disponible facilmente. | P36: =SUM(J36:O36) -> 0
C37: 18 | D37: Limpieza mas alla de lo propio | F37: Todo el area se ve ordenada | P37: =SUM(J37:O37) -> 0
C38: 19 | D38: Disciplina de limpieza | F38: Cuando hay tiempo disponible, los alumnos habitualmente y automáticamente ordenan y limpian sus espacios de trabajo. | P38: =SUM(J38:O38) -> 0
C39: 20 | D39: Plan de mejoras | F39: Donde sea aplicable se implementan nuevas estrategias para evitar la generación de residuos, según principios 5S. Existe un programa con responsables y plazos. | P39: =SUM(J39:O39) -> 0
N40: TOTAL | P40: =SUM(P34:P39) -> 0
B42: ESTANDARIZACION | C42: 21 | D42: Control visual | F42: Tableros o sistemas de información digitales son accesible al personal del area | P42: =SUM(J42:O42) -> 0
C43: 22 | D43: Auditorias 5S | F43: Se realizan auditorias de 5S regularmente y los resultados son expuestos y compartidos. | P43: =SUM(J43:O43) -> 0
C44: 23 | D44: Seguridad | F44: Los alumnos conocen y respetan las normas de seguridad del área. | P44: =SUM(J44:O44) -> 0
C45: 24 | D45: Actividadades estándar | F45: Se utilizan estandares para mantener organizadas y productivas las actividades. | P45: =SUM(J45:O45) -> 0
C46: 25 | D46: Revision del ciclo 5S | F46: Se aplican consistentemente las 3 primeras S. | P46: =SUM(J46:O46) -> 0
N47: TOTAL | P47: =SUM(P42:P46) -> 0
B49: DISCIPLINA | C49: 26 | D49: Mantenimiento | F49: El equipo es capacitado en 5S, se realizan actividades sistematicas, los docentes y alumnos se involucran. | P49: =SUM(J49:O49) -> 0
C50: 27 | D50: Area de responsabilidad | F50: Cumplen las normas del codigo de convivencia. Se utilizan los elementos de protección personal, incluyendo el uniforme. Se investigan y divulgan los accidentes. | P50: =SUM(J50:O50) -> 0
...

Sheet TALLER ROBOTICA
B2: AUDITORIA MENSUAL 5S
B4: CB | D4: AULA /TALLER | H4: RESPONSABLE AULA/TALLER: | O4: CALIFICACION PREVIA:
B5: TEL | D5: CLASE: | H5: AUDITOR: | O5: CALIFICACION FINAL: | P5: =+P56 -> 0
B6: TEM | D6: ASIGNATURA: | H6: FECHA: | O6: NIVEL ACTUAL:
C9: Nivel | D9: 0 | E9: 1 | F9: 2 | G9: 3 | H9: 4 | I9: 5
C10: Status | D10: No Iniciado | E10: Actividad de inicio | F10: Amplia Actividad | G10: Nivel minimo requerido | H10: Nivle Medio | I10: Mejor Practica
C11: Puntos | D11: 0-10 | E11: 10-40 | F11: 40-70 | G11: 70-100 | H11: 100-130 | I11: 130-150
J14: PUNTAJE | Q14: OBSERVACIONES
J15: 0 | K15: 1 | L15: 2 | M15: 3 | N15: 4 | O15: 5 | P15: Total
B16: SELECCIÓN | C16: 1 | D16: Componentes, materiales y partes | F16: Se encuentran los niveles necesarios de materiales/elementos. Residuos y elementos sin uso están en contenedores claramente identificados. | P16: =SUM(J16:O16) -> 0
C17: 2 | D17: Maquinas, gabinetes, muebles, bancos, escritorios | F17: Solo los elementos necesarios estan en uso y se encuentran operables. No hay elementos rotos que deban ser descartados o reparados. | P17: =SUM(J17:O17) -> 0
C18: 3 | D18: Herramientas y equipos | F18: Todas las herramientas necsarias están en uso y operables. Hay cosas innecesarias en los armarios. | P18: =SUM(J18:O18) -> 0
C19: 4 | D19: Cartelera / Información | F19: ¿Los registros de actividad con tarjetas rojas y hallazgos estan actualizados? | P19: =SUM(J19:O19) -> 0
C20: 5 | D20: Ambiente | F20: Existen objetos innecesarios o basura en el piso. Las areas de circulación están libres de objetos. | P20: =SUM(J20:O20) -> 0
N21: TOTAL | P21: =SUM(P16:P20) -> 0
B23: ORDEN | C23: 6 | D23: Lay out | F23: Maquinas, herramientas, estanterias, contenedores estan dispuestos de manera lógica y promoviendo un flujo de trabajo agil y ordenado en el área. | P23: =SUM(J23:O23) -> 0
C24: 7 | D24: Marcado de pasillos y suelos | F24: Los pasillos y sendas se encuentran marcados y liberados | P24: =SUM(J24:O24) -> 0
C25: 8 | D25: Documentación y señales visuales | F25: Se encuentran solo los documentos /carpetas necesarias para el trabajo. Están guardadas, ordenadas y rotuladas. | P25: =SUM(J25:O25) -> 0
C26: 9 | D26: Control visual y almacenamiento | F26: Los elementos estan correctamente identificados. La cartelería es clara, apropiada y prolija. | P26: =SUM(J26:O26) -> 0
C27: 10 | D27: Lugares para herramientas y accesorios | F27: Herramientas y accesorios son arreglados y guardados en orden, limpios y en un lugar específico de facil localización. | P27: =SUM(J27:O27) -> 0
C28: 11 | D28: Elementos fuera de lugar | F28: Hay elementos sin ubicación especifica. Obstruyen el orden y limpieza del lugar. | P28: =SUM(J28:O28) -> 0
C29: 12 | D29: Almacenamiento de materiales peligrosos | F29: Liquidos, solventes y otros quimicos se encuentran claramente identificados. Se encuentran disponibles sus hojas de seguridad. No hay derrames. | P29: =SUM(J29:O29) -> 0
C30: 13 | D30: Salidas de emergencia. Elementos de seguridad | F30: Los elementos de seguridad están visibles y sin obstrucciones. Las rutas de escape y los lugares de peligro estan identificados y despejados. | P30: =SUM(J30:O30) -> 0
C31: 14 | D31: Mantenimiento de equipos | F31: Se llevan registros del mantenimiento de los equipos. Se informan posibles mejoras. | P31: =SUM(J31:O31) -> 0
N32: TOTAL | P32: =SUM(P23:P31) -> 0
B34: LIMPIEZA | C34: 15 | D34: Estado de pisos / tachos | F34: Los pisos están limpios, libres de suciedad, residuos o líquidos. El exterior de los tachos está limpio e identificado. | P34: =SUM(J34:O34) -> 0
C35: 16 | D35: Maquinas / equipos | F35: Se realiza una rutina de limpieza. No hay tierra, suciedad, residuos entre o en las máquinas o equipos. | P35: =SUM(J35:O35) -> 0
C36: 17 | D36: Elementos de limpieza | F36: Todo el equipo de limpieza está ubicado en un lugar específico y disponible facilmente. | P36: =SUM(J36:O36) -> 0
C37: 18 | D37: Limpieza mas alla de lo propio | F37: Todo el area se ve ordenada | P37: =SUM(J37:O37) -> 0
C38: 19 | D38: Disciplina de limpieza | F38: Cuando hay tiempo disponible, los alumnos habitualmente y automáticamente ordenan y limpian sus espacios de trabajo. | P38: =SUM(J38:O38) -> 0
C39: 20 | D39: Plan de mejoras | F39: Donde sea aplicable se implementan nuevas estrategias para evitar la generación de residuos, según principios 5S. Existe un programa con responsables y plazos. | P39: =SUM(J39:O39) -> 0
N40: TOTAL | P40: =SUM(P34:P39) -> 0
B42: ESTANDARIZACION | C42: 21 | D42: Control visual | F42: Tableros o sistemas de información digitales son accesible al personal del area | P42: =SUM(J42:O42) -> 0
C43: 22 | D43: Auditorias 5S | F43: Se realizan auditorias de 5S regularmente y los resultados son expuestos y compartidos. | P43: =SUM(J43:O43) -> 0
C44: 23 | D44: Seguridad | F44: Los alumnos conocen y respetan las normas de seguridad del área. | P44: =SUM(J44:O44) -> 0
C45: 24 | D45: Actividadades estándar | F45: Se utilizan estandares para mantener organizadas y productivas las actividades. | P45: =SUM(J45:O45) -> 0
C46: 25 | D46: Revision del ciclo 5S | F46: Se aplican consistentemente las 3 primeras S. | P46: =SUM(J46:O46) -> 0
N47: TOTAL | P47: =SUM(P42:P46) -> 0
B49: DISCIPLINA | C49: 26 | D49: Mantenimiento | F49: El equipo es capacitado en 5S, se realizan actividades sistematicas, los docentes y alumnos se involucran. | P49: =SUM(J49:O49) -> 0
C50: 27 | D50: Area de responsabilidad | F50: Cumplen las normas del codigo de convivencia. Se utilizan los elementos de protección personal, incluyendo el uniforme. Se investigan y divulgan los accidentes. | P50: =SUM(J50:O50) -> 0
...

Sheet HISTORICO
B1: TALLER 1 | C1: FECHA
C2: 45446
B3: SELECCIÓN | C3: =+'TALLER 1'!$P59 -> 0 | D3: =+'TALLER 1'!$P59 -> 0 | E3: =+'TALLER 1'!$P59 -> 0 | F3: =+'TALLER 1'!$P59 -> 0 | G3: =+'TALLER 1'!$P59 -> 0 | H3: =+'TALLER 1'!$P59 -> 0 | I3: =+'TALLER 1'!$P59 -> 0 | J3: =+'TALLER 1'!$P59 -> 0
B4: ORDEN | C4: =+'TALLER 1'!$P60 -> 0 | D4: =+'TALLER 1'!$P60 -> 0 | E4: =+'TALLER 1'!$P60 -> 0 | F4: =+'TALLER 1'!$P60 -> 0 | G4: =+'TALLER 1'!$P60 -> 0 | H4: =+'TALLER 1'!$P60 -> 0 | I4: =+'TALLER 1'!$P60 -> 0 | J4: =+'TALLER 1'!$P60 -> 0
B5: LIMPIEZA | C5: =+'TALLER 1'!$P61 -> 0 | D5: =+'TALLER 1'!$P61 -> 0 | E5: =+'TALLER 1'!$P61 -> 0 | F5: =+'TALLER 1'!$P61 -> 0 | G5: =+'TALLER 1'!$P61 -> 0 | H5: =+'TALLER 1'!$P61 -> 0 | I5: =+'TALLER 1'!$P61 -> 0 | J5: =+'TALLER 1'!$P61 -> 0
B6: ESTANDARIZACIÓN | C6: =+'TALLER 1'!$P62 -> 0 | D6: =+'TALLER 1'!$P62 -> 0 | E6: =+'TALLER 1'!$P62 -> 0 | F6: =+'TALLER 1'!$P62 -> 0 | G6: =+'TALLER 1'!$P62 -> 0 | H6: =+'TALLER 1'!$P62 -> 0 | I6: =+'TALLER 1'!$P62 -> 0 | J6: =+'TALLER 1'!$P62 -> 0
B7: DISCIPLINA | C7: =+'TALLER 1'!$P63 -> 0 | D7: =+'TALLER 1'!$P63 -> 0 | E7: =+'TALLER 1'!$P63 -> 0 | F7: =+'TALLER 1'!$P63 -> 0 | G7: =+'TALLER 1'!$P63 -> 0 | H7: =+'TALLER 1'!$P63 -> 0 | I7: =+'TALLER 1'!$P63 -> 0 | J7: =+'TALLER 1'!$P63 -> 0
B8: TOTAL | C8: =+'TALLER 1'!$P64 -> 0 | D8: =+'TALLER 1'!$P64 -> 0 | E8: =+'TALLER 1'!$P64 -> 0 | F8: =+'TALLER 1'!$P64 -> 0 | G8: =+'TALLER 1'!$P64 -> 0 | H8: =+'TALLER 1'!$P64 -> 0 | I8: =+'TALLER 1'!$P64 -> 0 | J8: =+'TALLER 1'!$P64 -> 0
B10: TALLER 2 | C10: FECHA
B12: SELECCIÓN | C12: =+'TALLER 2'!$P59 -> 0 | D12: =+'TALLER 2'!$P59 -> 0 | E12: =+'TALLER 2'!$P59 -> 0 | F12: =+'TALLER 2'!$P59 -> 0 | G12: =+'TALLER 2'!$P59 -> 0 | H12: =+'TALLER 2'!$P59 -> 0 | I12: =+'TALLER 2'!$P59 -> 0 | J12: =+'TALLER 2'!$P59 -> 0
B13: ORDEN | C13: =+'TALLER 2'!$P60 -> 0 | D13: =+'TALLER 2'!$P60 -> 0 | E13: =+'TALLER 2'!$P60 -> 0 | F13: =+'TALLER 2'!$P60 -> 0 | G13: =+'TALLER 2'!$P60 -> 0 | H13: =+'TALLER 2'!$P60 -> 0 | I13: =+'TALLER 2'!$P60 -> 0 | J13: =+'TALLER 2'!$P60 -> 0
B14: LIMPIEZA | C14: =+'TALLER 2'!$P61 -> 0 | D14: =+'TALLER 2'!$P61 -> 0 | E14: =+'TALLER 2'!$P61 -> 0 | F14: =+'TALLER 2'!$P61 -> 0 | G14: =+'TALLER 2'!$P61 -> 0 | H14: =+'TALLER 2'!$P61 -> 0 | I14: =+'TALLER 2'!$P61 -> 0 | J14: =+'TALLER 2'!$P61 -> 0
B15: ESTANDARIZACIÓN | C15: =+'TALLER 2'!$P62 -> 0 | D15: =+'TALLER 2'!$P62 -> 0 | E15: =+'TALLER 2'!$P62 -> 0 | F15: =+'TALLER 2'!$P62 -> 0 | G15: =+'TALLER 2'!$P62 -> 0 | H15: =+'TALLER 2'!$P62 -> 0 | I15: =+'TALLER 2'!$P62 -> 0 | J15: =+'TALLER 2'!$P62 -> 0
B16: DISCIPLINA | C16: =+'TALLER 2'!$P63 -> 0 | D16: =+'TALLER 2'!$P63 -> 0 | E16: =+'TALLER 2'!$P63 -> 0 | F16: =+'TALLER 2'!$P63 -> 0 | G16: =+'TALLER 2'!$P63 -> 0 | H16: =+'TALLER 2'!$P63 -> 0 | I16: =+'TALLER 2'!$P63 -> 0 | J16: =+'TALLER 2'!$P63 -> 0
B17: TOTAL | C17: =+'TALLER 2'!$P64 -> 0 | D17: =+'TALLER 2'!$P64 -> 0 | E17: =+'TALLER 2'!$P64 -> 0 | F17: =+'TALLER 2'!$P64 -> 0 | G17: =+'TALLER 2'!$P64 -> 0 | H17: =+'TALLER 2'!$P64 -> 0 | I17: =+'TALLER 2'!$P64 -> 0 | J17: =+'TALLER 2'!$P64 -> 0
B19: TALLER ROBÓTICA | C19: FECHA
B21: SELECCIÓN | C21: =+'TALLER ROBOTICA'!$P59 -> 0 | D21: =+'TALLER ROBOTICA'!$P59 -> 0 | E21: =+'TALLER ROBOTICA'!$P59 -> 0 | F21: =+'TALLER ROBOTICA'!$P59 -> 0 | G21: =+'TALLER ROBOTICA'!$P59 -> 0 | H21: =+'TALLER ROBOTICA'!$P59 -> 0 | I21: =+'TALLER ROBOTICA'!$P59 -> 0 | J21: =+'TALLER ROBOTICA'!$P59 -> 0
B22: ORDEN | C22: =+'TALLER ROBOTICA'!$P60 -> 0 | D22: =+'TALLER ROBOTICA'!$P60 -> 0 | E22: =+'TALLER ROBOTICA'!$P60 -> 0 | F22: =+'TALLER ROBOTICA'!$P60 -> 0 | G22: =+'TALLER ROBOTICA'!$P60 -> 0 | H22: =+'TALLER ROBOTICA'!$P60 -> 0 | I22: =+'TALLER ROBOTICA'!$P60 -> 0 | J22: =+'TALLER ROBOTICA'!$P60 -> 0
B23: LIMPIEZA | C23: =+'TALLER ROBOTICA'!$P61 -> 0 | D23: =+'TALLER ROBOTICA'!$P61 -> 0 | E23: =+'TALLER ROBOTICA'!$P61 -> 0 | F23: =+'TALLER ROBOTICA'!$P61 -> 0 | G23: =+'TALLER ROBOTICA'!$P61 -> 0 | H23: =+'TALLER ROBOTICA'!$P61 -> 0 | I23: =+'TALLER ROBOTICA'!$P61 -> 0 | J23: =+'TALLER ROBOTICA'!$P61 -> 0
B24: ESTANDARIZACIÓN | C24: =+'TALLER ROBOTICA'!$P62 -> 0 | D24: =+'TALLER ROBOTICA'!$P62 -> 0 | E24: =+'TALLER ROBOTICA'!$P62 -> 0 | F24: =+'TALLER ROBOTICA'!$P62 -> 0 | G24: =+'TALLER ROBOTICA'!$P62 -> 0 | H24: =+'TALLER ROBOTICA'!$P62 -> 0 | I24: =+'TALLER ROBOTICA'!$P62 -> 0 | J24: =+'TALLER ROBOTICA'!$P62 -> 0
B25: DISCIPLINA | C25: =+'TALLER ROBOTICA'!$P63 -> 0 | D25: =+'TALLER ROBOTICA'!$P63 -> 0 | E25: =+'TALLER ROBOTICA'!$P63 -> 0 | F25: =+'TALLER ROBOTICA'!$P63 -> 0 | G25: =+'TALLER ROBOTICA'!$P63 -> 0 | H25: =+'TALLER ROBOTICA'!$P63 -> 0 | I25: =+'TALLER ROBOTICA'!$P63 -> 0 | J25: =+'TALLER ROBOTICA'!$P63 -> 0
B26: TOTAL | C26: =+'TALLER ROBOTICA'!$P64 -> 0 | D26: =+'TALLER ROBOTICA'!$P64 -> 0 | E26: =+'TALLER ROBOTICA'!$P64 -> 0 | F26: =+'TALLER ROBOTICA'!$P64 -> 0 | G26: =+'TALLER ROBOTICA'!$P64 -> 0 | H26: =+'TALLER ROBOTICA'!$P64 -> 0 | I26: =+'TALLER ROBOTICA'!$P64 -> 0 | J26: =+'TALLER ROBOTICA'!$P64 -> 0
